Workbook

Sheet Panduan
B2: INSTRUMEN SELF-ASSESSMENT AKREDITASI
B3: LABORATORIUM KESEHATAN MASYARAKAT (LABKESMAS)
B5: Disusun untuk Koordinator Wilayah Kalimantan Tengah — Komite Akreditasi Kesehatan Lanjutan (KAKL)
B7: A. DASAR HUKUM
B8: • Peraturan Menteri Kesehatan Nomor 34 Tahun 2022 tentang Akreditasi Puskesmas, Klinik, Laboratorium Kesehatan, Unit Transfusi Darah, Tempat Praktik Mandiri Dokter, dan Tempat Praktik Mandiri Dokter Gigi.
B9: • Standar Akreditasi Laboratorium Kesehatan (rujukan KMK terkait — sesuai template resmi yang diberikan Bapak Hary Satrisno).
B11: B. SUMBER KONTEN
B12: Seluruh Standar, Elemen Penilaian, metode telusur, dan bukti pada workbook ini diambil langsung dari template resmi Self Assessment Laboratorium Kesehatan yang diberikan Bapak Hary Satrisno — bukan rekonstruksi dari pencarian web.
B14: C. STRUKTUR BAB (7 Bab)
B15: • Bab I. Sasaran Keselamatan Pasien (SKP)
B16: • Bab II. Tata Kelola Kepemimpinan (TKK)
B17: • Bab III. Manajemen Informasi (MI)
... B42: 4. Ringkasan capaian per Standar dan per Bab terhitung otomatis (EP TDD dikeluarkan dari penyebut).

Sheet Bab I - SKP (Rinci)
A1: Bab I. SASARAN KESELAMATAN PASIEN (SKP) — KONTEN RESMI LENGKAP
A2: Sumber: Template Self Assessment Laboratorium Kesehatan resmi yang diberikan Bapak Hary Satrisno. Redaksi Elemen Penilaian dan Bukti/Telusur adalah teks ASLI.
A4: Standar | B4: No. EP | C4: Elemen Penilaian | D4: Skor Diri (0/5/10/TDD) | E4: Metode Telusur & Bukti | F4: Catatan / Rencana Tindak Lanjut
A5: Standar SKP 1 — Laboratorium Kesehatan mengembangkan dan mengimplementasikan proses untuk meningkatkan ketepatan identifikasi.
A6: Standar SKP 1 | B6: 1 | C6: 1) Terdapat kebijakan, pedoman dan prosedur yang mengatur identifikasi pasien dengan menggunakan minimal dua dari empat identitas. | E6: [R] Regulasi: (Kebijakan/pedoman/prosedur identifikasi pasien)
A7: Standar SKP 1 | B7: 2 | C7: 2) Terdapat bukti Identifikasi dilakukan mulai dari pendaftaran sampai penyerahan hasil. | E7: [D O W] Bukti pelaksanaan identifikasi dari pendaftaran sampai penyerahan hasil Observasi pelaksanaan identifikasi dari pendaftaran sampai penyerahan hasil Bagian Administrasi, Koordinator Laboratorium, ATLM/ Pelaksana
A8: Standar SKP 2 — Laboratorium kesehatan menerapkan proses komunikasi efektif dalam memberikan pelayanan baik secara verbal dan atau komunikasi melalui telepon dalam me
A9: Standar SKP 2 | B9: 1 | C9: 1) Terdapat bukti pelaporan dan penyerahan hasil kritis | E9: [D W S] Bukti pelaporan dan penyerahan hasil kritis Koordinator Labkes, ATLM/Pelaksana Simulasi pelaporan dan penyerahan hasil kritis
A10: Standar SKP 2 | B10: 2 | C10: 2) Terdapat bukti evaluasi dan tindak lanjut pelaksanaan pelaporan hasil kritis | E10: [D] Bukti evaluasi dan tindak lanjut pelaporan hasil kritis
A11: Standar SKP 3 — Infeksi yang terjadi sebagai dampak dari pelayanan kesehatan adalah merupakan ancaman keselamatan bagi penerima layanan. Laboratorium kesehatan mengad
A12: Standar SKP 3 | B12: 1 | C12: 1) Terdapat kebijakan, pedoman dan prosedur tentang kebersihan tangan. | E12: [R] Regulasi: (Kebijakan/pedoman/prosedur/ program kebersihan tangan).
A13: Standar SKP 3 | B13: 2 | C13: 2) Terdapat bukti implementasi program kebersihan tangan bagi seluruh petugas. | E13: [D O S] Bukti implementasi program kebersihan tangan bagi seluruh petugas termasuk hasil pengukuran INM Kepatuhan Kebersihan Tangan. Bukti kelengkapan fasilitas kebersihan tangan dan penerapan pelaksanaan kebersihan tangan bagi seluruh petugas. Peragaan Kebersihan Tangan
A15: RINGKASAN CAPAIAN BAB I
A16: Standar | B16: Jumlah EP | C16: Total Skor | D16: Skor Maksimal | E16: Capaian (%)
A17: Standar SKP 1 | B17: 2 | C17: =SUMPRODUCT((D6:D7<>"TDD")*IFERROR(D6:D7,0)) -> 0 | D17: =COUNTIF(D6:D7,"<>TDD")*10 -> 20 | E17: =IFERROR(C17/D17,0) -> 0
A18: Standar SKP 2 | B18: 2 | C18: =SUMPRODUCT((D9:D10<>"TDD")*IFERROR(D9:D10,0)) -> 0 | D18: =COUNTIF(D9:D10,"<>TDD")*10 -> 20 | E18: =IFERROR(C18/D18,0) -> 0
A19: Standar SKP 3 | B19: 2 | C19: =SUMPRODUCT((D12:D13<>"TDD")*IFERROR(D12:D13,0)) -> 0 | D19: =COUNTIF(D12:D13,"<>TDD")*10 -> 20 | E19: =IFERROR(C19/D19,0) -> 0
A20: TOTAL BAB I | B20: =SUM(B17:B19) -> 6 | C20: =SUM(C17:C19) -> 0 | D20: =SUM(D17:D19) -> 60 | E20: =IFERROR(C20/D20,0) -> 0

Sheet Bab II - TKK (Rinci)
A1: Bab II. TATA KELOLA KEPEMIMPINAN (TKK) — KONTEN RESMI LENGKAP
A2: Sumber: Template Self Assessment Laboratorium Kesehatan resmi yang diberikan Bapak Hary Satrisno. Redaksi Elemen Penilaian dan Bukti/Telusur adalah teks ASLI.
A4: Standar | B4: No. EP | C4: Elemen Penilaian | D4: Skor Diri (0/5/10/TDD) | E4: Metode Telusur & Bukti | F4: Catatan / Rencana Tindak Lanjut
A5: Standar TKK 1 Penetapan visi dan misi — Pimpinan laboratorium kesehatan menetapkan visi dan misi serta perencanaan kegiatan yang mendukung penyelenggaraan pelayanan laboratorium kesehatan.
A6: Standar TKK 1 Penetapan visi dan misi | B6: 1 | C6: 1) Terdapat bukti penyusunan visi dan misi Laboratorium Kesehatan, serta penetapan visi dan misi laboratorium kesehatan | E6: [D R] Bukti pertemuan penyusunan visi dan misi Laboratorium Kesehatan oleh semua petugas Laboratorium Kesehatan (undangan, daftar hadir, notulen, dokumentasi, materi) Regulasi tentang penetapan visi dan misi
A7: Standar TKK 1 Penetapan visi dan misi | B7: 2 | C7: 2) Terdapat bukti sosialisasi dan pemahaman visi dan misi kepada seluruh petugas laboratorium kesehatan, serta evaluasi visi dan misi laboratorium kesehatan | E7: [D W] Bukti sosialisasi visi dan misi kepada seluruh petugas Bukti evaluasi visi dan misi laboratorium kesehatan Bukti pemahaman visi dan misi Laboratorium Kesehatan
A8: Standar TKK 1.1.1 Kualifikasi pimpinan laboratorium kesehatan — Pimpinan laboratorium kesehatan memenuhi kualifikasi sesuai peraturan perundang-undangan
A9: Standar TKK 1.1.1 Kualifikasi pimpinan laboratorium kesehatan | B9: 1 | C9: 1) Kepala laboratorium kesehatan memenuhi kualifikasi sesuai dengan ketentuan peraturan perundang-undangan | E9: [R D] Regulasi tentang Kualifikasi Kepala Laboratorium Kesehatan sesuai dengan ketentuan peraturan perundang- undangan Dokumen file kepegawaian kepala laboratorium kesehatan
A10: Standar TKK 1.1.1 Kualifikasi pimpinan laboratorium kesehatan | B10: 2 | C10: 2) Kepala laboratorium kesehatan mempunyai uraian tugas sesuai dengan ketentuan peraturan perundang-undangan | E10: [R D] Regulasi penetapan Kepala Laboratorium Kesehatan beserta lampiran uraian tugas. Bukti implementasi tugas Kepala Laboratorium Kesehatan sesuai uraian tugas.
A11: Standar TKK 1.1.1 Kualifikasi pimpinan laboratorium kesehatan | B11: 3 | C11: 3) Kepala Laboratorium Kesehatan melakukan pelaporan berkala kepada pemilik | E11: [D] Bukti laporan Kepala Laboratorium Kesehatan kepada pemilik
A12: Standar TKK 2 Koordinasi dengan pihak terkait atau pemangku kepentingan — Pimpinan laboratorium kesehatan melakukan koordinasi dengan pihak terkait atau pemangku kepentingan untuk menentukan jenis dan lingkup pelayanan labor
A13: Standar TKK 2 Koordinasi dengan pihak terkait atau pemangku kepentingan | B13: 1 | C13: 1) Terdapat bukti koordinasi dengan pihak terkait untuk menentukan jenis pelayanan laboratorium kesehatan yang mencakup angka 1) sampai angka 6) paling singkat 1 (satu) tahun sekali. | E13: [D] Bukti koordinasi dengan pihak terkait atau pemangku kepentingan untuk menentukan jenis pelayanan laboratorium kesehatan yang meliputi angka 1) sampai angka 6) paling singkat 1 (satu) tahun sekali
A14: Standar TKK 2 Koordinasi dengan pihak terkait atau pemangku kepentingan | B14: 2 | C14: 2) Terdapat kebijakan tentang jenis pelayanan laboratorium kesehatan | E14: [R] Regulasi tentang jenis pelayanan laboratorium kesehatan
A15: Standar TKK 2.1 Perencanaan ketersediaan sumber daya yang dibutuhkan — Pimpinan laboratorium kesehatan merencanakan dan menjamin ketersediaan sumber daya yang dibutuhkan dengan mengutamakan mutu dan keselamatan
A16: Standar TKK 2.1 Perencanaan ketersediaan sumber daya yang dibutuhkan | B16: 1 | C16: 1) Tersedia data yang digunakan sebagai dasar penyusunan rencana kebutuhan dan pemilihan teknologi tepat guna. | E16: [D] Data yang digunakan sebagai dasar penyusunan rencana kebutuhan dan pemilihan teknologi tepat guna.
A17: Standar TKK 2.1 Perencanaan ketersediaan sumber daya yang dibutuhkan | B17: 2 | C17: 2) Terdapat perencanaan laboratorium kesehatan untuk menjamin terlaksananya pelayanan yang mencakup angka 1) sampai angka 5). | E17: [D W] Perencanaan laboratorium kesehatan Kepala Labkes, Kepala Tata Usaha/Kepegawaian Labkes, Penanggung Jawab Unit dan SDM Labkes
A18: Standar TKK 2.1 Perencanaan ketersediaan sumber daya yang dibutuhkan | B18: 3 | C18: 3) Tersedia sumber daya laboratorium kesehatan yang mencakup angka 1) sampai angka 5). | E18: [D] Daftar ketersediaan sumberdaya laboratorium kesehatan mencakup angka 1) sampai angka 5)
A19: Standar TKK 2.1 Perencanaan ketersediaan sumber daya yang dibutuhkan | B19: 4 | C19: 4) Terdapat bukti evaluasi perencanaan dan ketersediaan sumber daya yang dibutuhkan | E19: [D] Bukti evaluasi perencanaan dan ketersediaan sumberdaya
A20: Standar TKK 2.2 Perjanjian kerja sama — Pimpinan laboratorium kesehatan menetapkan perjanjian kerja sama
A21: Standar TKK 2.2 Perjanjian kerja sama | B21: 1 | C21: 1) Terdapat perjanjian kerja sama tertulis. | E21: [D] Bukti perjanjian kerja sama tertulis
A22: Standar TKK 2.2 Perjanjian kerja sama | B22: 2 | C22: 2) Terdapat kriteria penentuan kerja sama dengan pihak ketiga. | E22: [R W] Regulasi tentang kriteria penentuan perjanjian kerja sama dengan pihak ketiga Pimpinan laboratorium kesehatan
A23: Standar TKK 2.2.1 Perjanjian kerja sama dengan pihak ketiga — Laboratorium kesehatan menetapkan perjanjian kerja sama dengan pihak ketiga yang telah memiliki izin/lisensi dan terakreditasi
A24: Standar TKK 2.2.1 Perjanjian kerja sama dengan pihak ketiga | B24: 1 | C24: 1) Terdapat salinan perizinan/lisensi pihak ketiga yang bekerja sama sesuai dengan ketentuan peraturan perundang-undangan. | E24: [D] Salinan perijinan/ lisensi pihak ketiga yang bekerja sama sesuai dengan ketentuan peraturan perundang-undangan
A25: Standar TKK 2.2.1 Perjanjian kerja sama dengan pihak ketiga | B25: 2 | C25: 2) Terdapat salinan sertifikat akreditasi atau sertifikasi pihak ketiga yang bekerja sama oleh lembaga yang diakui pemerintah. | E25: [D] Salinan sertifikat akreditasi atau sertifikasi pihak ketiga yang bekerja sama oleh lembaga yang diakui pemerintah yang masih berlaku
A26: Standar TKK 2.2.2 Evaluasi terhadap perjanjian kerja sama — Pimpinan laboratorium kesehatan bertanggung jawab melakukan evaluasi terhadap perjanjian kerja sama.
A27: Standar TKK 2.2.2 Evaluasi terhadap perjanjian kerja sama | B27: 1 | C27: 1) Terdapat kebijakan pelaksanaan evaluasi dan tindak lanjut terhadap perjanjian kerja sama. | E27: [R] Regulasi : kebijakan pelaksanaan evaluasi dan tindak lanjut terhadap perjanjian kerja sama
A28: Standar TKK 2.2.2 Evaluasi terhadap perjanjian kerja sama | B28: 2 | C28: 2) Terdapat bukti dokumentasi pelaksanaan evaluasi dan tindak lanjut perjanjian kerja sama. | E28: [D] Bukti pelaksanaan evaluasi dan tindak lanjut perjanjian kerja sama
A29: Standar TKK 2.3 Pelayanan Point Of Care Test (POCT) — SDM yang kompeten dan berwenang melaksanakan dan memantau pelayanan Point Of Care Test (POCT).
A30: Standar TKK 2.3 Pelayanan Point Of Care Test (POCT) | B30: 1 | C30: 1) Terdapat SDM yang kompeten dan berwenang, dalam pelaksanaan dan pemantauan POCT. | E30: [D W] File kepegawaian berisi pembuktian kompetensi dan kewenangan SDM yang melaksanakan dan memantau POCT ( uraian tugas, sertifikat pelatihan POCT) Petugas POCT
A31: Standar TKK 2.3 Pelayanan Point Of Care Test (POCT) | B31: 2 | C31: 2) Terdapat prosedur pelaporan hasil POCT, termasuk hasil kritis | E31: [R] Regulasi :Prosedur pelaporan hasil POCT, termasuk hasil kritis
A32: Standar TKK 2.3 Pelayanan Point Of Care Test (POCT) | B32: 3 | C32: 3) Pelaksanaan POCT dipantau dan dievaluasi, serta dilakukan upaya tindak lanjut untuk peningkatan mutu pelayanan. | E32: [D] Bukti pemantauan, evaluasi dan tindak lanjut pelaksanaan POCT untuk peningkatan mutu pelayanan
A33: Standar TKK 3.1 Orientasi terhadap kebutuhan pelanggan — Pelayanan laboratorium kesehatan berorientasi terhadap kebutuhan pelanggan
A34: Standar TKK 3.1 Orientasi terhadap kebutuhan pelanggan | B34: 1 | C34: 1) Dilakukan survei kepuasan pelanggan. | E34: [D] Hasil survei kepuasan pelanggan
A35: Standar TKK 3.1 Orientasi terhadap kebutuhan pelanggan | B35: 2 | C35: 2) Dilakukan analisis, evaluasi dan tindak lanjut hasil survei kepuasan pelanggan | E35: [D] Bukti analisis, evaluasi dan tindak lanjut hasil survei kepuasan pelanggan
A36: Standar TKK 3.2 Prosedur pelaporan hasil kritis — Terdapat prosedur pelaporan hasil kritis
A37: Standar TKK 3.2 Prosedur pelaporan hasil kritis | B37: 1 | C37: 1) Terdapat penetapan hasil kritis. | E37: [R] Regulasi penetapan hasil kritis
A38: Standar TKK 3.2 Prosedur pelaporan hasil kritis | B38: 2 | C38: 2) Terdapat prosedur pelaporan hasil kritis. | E38: [R] Regulasi : Prosedur pelaporan hasil kritis
A39: Standar TKK 4 Program peningkatan mutu pelayanan laboratorium kesehatan — Pimpinan laboratorium kesehatan menetapkan program peningkatan mutu pelayanan laboratorium kesehatan.
A40: Standar TKK 4 Program peningkatan mutu pelayanan laboratorium kesehatan | B40: 1 | C40: 1) Terdapat program peningkatan mutu | E40: [R] Regulasi : Program peningkatan mutu
A41: Standar TKK 4 Program peningkatan mutu pelayanan laboratorium kesehatan | B41: 2 | C41: 2) Program peningkatan mutu laboratorium kesehatan mencakup tujuan, target, indikator dan cara pengukuran pencapaian target. | E41: [R] Regulasi : Program peningkatan mutu labkes mencakup tujuan, target, indikator dan cara pengukuran pencapaian target
...

Sheet Bab III - MI (Rinci)
A1: Bab III. MANAJEMEN INFORMASI (MI) — KONTEN RESMI LENGKAP
A2: Sumber: Template Self Assessment Laboratorium Kesehatan resmi yang diberikan Bapak Hary Satrisno. Redaksi Elemen Penilaian dan Bukti/Telusur adalah teks ASLI.
A4: Standar | B4: No. EP | C4: Elemen Penilaian | D4: Skor Diri (0/5/10/TDD) | E4: Metode Telusur & Bukti | F4: Catatan / Rencana Tindak Lanjut
A5: Standar MI 1 Prosedur pengendalian dokumen — Terdapat prosedur pengendalian dokumen secara konsisten dan seragam
A6: Standar MI 1 Prosedur pengendalian dokumen | B6: 1 | C6: 1) Terdapat prosedur pengendalian dokumen yang mengacu kepada angka 1) sampai angka 7). | E6: [R] Regulasi : Prosedur pengendalian dokumen yang mengacu kepada angka 1) sampai angka 7)
A7: Standar MI 1 Prosedur pengendalian dokumen | B7: 2 | C7: 2) Terdapat format dokumen dan penyusunan dokumen sesuai dengan format yang telah ditetapkan. | E7: [R D] Regulasi : Tata Naskah Format dokumen
A8: Standar MI 2 Prosedur permintaan pemeriksaan — Terdapat prosedur permintaan pemeriksaan
A9: Standar MI 2 Prosedur permintaan pemeriksaan | B9: 1 | C9: 1) Terdapat prosedur permintaan pemeriksaan. | E9: [R] Regulasi : Prosedur permintaan pemeriksaan
A10: Standar MI 2 Prosedur permintaan pemeriksaan | B10: 2 | C10: 2) Terdapat kelengkapan identitas sesuai kriteria yang mencakup huruf a) sampai huruf n) pada angka 1) untuk laboratorium medis dan huruf a) sampai huruf j) pada angka 2) untuk laboratorium kesehatan masyarakat. | E10: [D] Formulir permintaan pemeriksaan sesuai kriteria yang mencakup huruf a) sampai huruf n) pada angka 1) untuk laboratorium medis dan huruf a) sampai huruf j) pada angka 2) untuk laboratorium kesehatan masyarakat.
A11: Standar MI 2 Prosedur permintaan pemeriksaan | B11: 3 | C11: 3) Terdapat bukti implementasi prosedur. | E11: [D] Bukti kepatuhan kelengkapan pengisian formulir permintaan pemeriksaan
A12: Standar MI 2.1 Prosedur pengambilan sampel/spesimen — Terdapat prosedur pengambilan sampel/spesimen untuk setiap pemeriksaan yang ada di laboratorium kesehatan
A13: Standar MI 2.1 Prosedur pengambilan sampel/spesimen | B13: 1 | C13: 1) Tersedia form permintaan pemeriksaan yang berisi jenis pelayanan serta dilengkapi dengan lembar persetujuan. | E13: [D] Form permintaan pemeriksaan yang dilengkapi lembar persetujuan
A14: Standar MI 2.1 Prosedur pengambilan sampel/spesimen | B14: 2 | C14: 2) Prosedur pengambilan sampel pada laboratorium kesehatan paling sedikit memuat huruf a) sampai huruf e). | E14: [R] Regulasi : Prosedur pengambilan sampel pada labkes paling sedikit memuat huruf a) sampai huruf e)
A15: Standar MI 2.1 Prosedur pengambilan sampel/spesimen | B15: 3 | C15: 3) Tersedia prosedur identifikasi pasien/sampel yang memuat paling sedikit 2 (dua) kriteria, contoh: nama, tanggal lahir, NIK, nomor register dan lain-lain. | E15: [R] Regulasi :Prosedur identifikasi pasien/sampel yang memuat palingsedikit 2 (dua) kriteria, contoh: nama, tanggal lahir, NIK, nomor register dan lain-lain.
A16: Standar MI 2.1 Prosedur pengambilan sampel/spesimen | B16: 4 | C16: 4) Penampungan sampel/spesimen diberi label identitas dengan paling sedikit 2 (dua) kriteria. | E16: [D O] Bukti pelabelan identitas pada penampungan sampel/spesimen Pelabelan identitas pada penampungan sampel/spesimen
A17: Standar MI 2.1 Prosedur pengambilan sampel/spesimen | B17: 5 | C17: 5) Ada bukti pengambilan sampel/spesimen mengikuti prosedur. | E17: [D W] Bukti penilaian kepatuhan terhadap prosedur pengambilan sampel/spesimen Petugas sampling
A18: Standar MI 2.2 Kebijakan dan prosedur penerimaan spesimen/sampel — Terdapat kebijakan dan prosedur penerimaan spesimen/sampel/
A19: Standar MI 2.2 Kebijakan dan prosedur penerimaan spesimen/sampel | B19: 1 | C19: 1) Terdapat prosedur penerimaan spesimen yang mencakup huruf a) sampai huruf h). | E19: [R] Regulasi :prosedur penerimaan spesimen/sampel yang mencakup huruf a) sampai huruf h)
A20: Standar MI 2.2 Kebijakan dan prosedur penerimaan spesimen/sampel | B20: 2 | C20: 2) Pelaksanaan penerimaan spesimen/sampel didokumentasikan. | E20: [D] Bukti dokumentasi penerimaan spesimen/sampel.
A21: Standar MI 2.2 Kebijakan dan prosedur penerimaan spesimen/sampel | B21: 3 | C21: 3) Tersedia kriteria penolakan spesimen/sampel. | E21: [R] Regulasi tentang kriteria penolakan spesimen/sampel
A22: Standar MI 3 Pemeriksaan laboratorium kesehatan dilaksanakan sesuai prosedur — Setiap pemeriksaan laboratorium dilaksanakan sesuai dengan prosedur
A23: Standar MI 3 Pemeriksaan laboratorium kesehatan dilaksanakan sesuai prosedur | B23: 1 | C23: 1) Tersedia prosedur pemeriksaan untuk setiap metode pemeriksaan yang memuat huruf a) sampai huruf i). | E23: [R] Regulasi : Prosedur pemeriksaan untuk setiap metode pemeriksaan yang memuat huruf a) sampai huruf i).
A24: Standar MI 3 Pemeriksaan laboratorium kesehatan dilaksanakan sesuai prosedur | B24: 2 | C24: 2) Terdapat bukti pelaksanaan prosedur untuk setiap pemeriksaan. | E24: [D] Bukti pelaksanaan prosedur untuk setiap pemeriksaan
A25: Standar MI 3 Pemeriksaan laboratorium kesehatan dilaksanakan sesuai prosedur | B25: 3 | C25: 3) Terdapat bukti kesesuaian rentang nilai rujukan yang ditetapkan dengan laporan hasil pemeriksaan. | E25: [D] Bukti laporan hasil pemeriksaan yang disertai nilai rujukan yang sudah ditetapkan.
A26: Standar MI 4 Kebijakan, pedoman/panduan, prosedur dan pelaksanaan pemantauan paska analitik — Laboratorium kesehatan menetapkan kebijakan, pedoman/panduan, prosedur dan pelaksanaan pemantauan paska analitik
A27: Standar MI 4 Kebijakan, pedoman/panduan, prosedur dan pelaksanaan pemantauan paska analitik | B27: 1 | C27: 1) Terdapat nama petugas yang melakukan pemeriksaan, verifikasi dan validasi. | E27: [D] Bukti laporan hasil pemeriksaan yang mencantumkan nama petugas yang melakukan pemeriksaan, verifikasi dan validasi.
A28: Standar MI 4 Kebijakan, pedoman/panduan, prosedur dan pelaksanaan pemantauan paska analitik | B28: 2 | C28: 2) Laporan hasil pemeriksaan mencakup huruf a) sampai huruf h) | E28: [D] Bukti laporan hasil pemeriksaan mencakup huruf a) sampai huruf h).
A29: Standar MI 4.1 Penetapan waktu tunggu pemeriksaan laboratorium kesehatan — Laboratorium kesehatan menetapkan waktu tunggu pemeriksaan laboratorium kesehatan.
A30: Standar MI 4.1 Penetapan waktu tunggu pemeriksaan laboratorium kesehatan | B30: 1 | C30: 1) Pimpinan laboratorium kesehatan menetapkan waktu tunggu setiap pemeriksaan. | E30: [R] Regulasi tentang penetapan waktu tunggu setiap pemeriksaan
A31: Standar MI 4.1 Penetapan waktu tunggu pemeriksaan laboratorium kesehatan | B31: 2 | C31: 2) Pimpinan laboratorium kesehatan menetapkan prosedur yang memuat cara untuk mengukur waktu tunggu pemeriksaan. | E31: [R] Regulasi : Prosedur yang memuat cara mengukur waktu tunggu pemeriksaan
A32: Standar MI 4.1 Penetapan waktu tunggu pemeriksaan laboratorium kesehatan | B32: 3 | C32: 3) Waktu tunggu pemeriksaan, diukur secara rutin, sesuai dengan prosedur. | E32: [D W] Bukti hasil pengukuran waktu tunggu pemeriksaan Penanggung jawab tiap unit, petugas administrasi dan petugas pelaksanaan pemeriksaan
A33: Standar MI 5 Prosedur Penyimpanan dan pemeliharaan dokumen, spesimen, sampel, sediaan, jaringan, dan blok — Penyimpanan dan pemeliharaan dokumen, spesimen, sampel, sediaan, jaringan, dan blok dilaksanakan sesuai prosedur.
A34: Standar MI 5 Prosedur Penyimpanan dan pemeliharaan dokumen, spesimen, sampel, sediaan, jaringan, dan blok | B34: 1 | C34: 1) Terdapat kebijakan dan prosedur tentang penyimpanan dokumen dan sampel, spesimen, sediaan, jaringan, blok untuk memenuhi huruf a) sampai huruf d) pada angka 1). | E34: [R] Regulasi : Kebijakan dan prosedur tentang penyimpanan dokumen dan sampel, spesimen, sediaan, jaringan, blok untuk memenuhi huruf a) sampai huruf d) pada angka 1).
A35: Standar MI 5 Prosedur Penyimpanan dan pemeliharaan dokumen, spesimen, sampel, sediaan, jaringan, dan blok | B35: 2 | C35: 2) Kebijakan mencakup syarat kondisi lingkungan yang layak untuk penyimpanan sampel, spesimen, sediaan, jaringan, blok. | E35: [R] Regulasi : Kebijakan tentang syarat kondisi lingkungan yang layak untuk penyimpanan sampel, spesimen, sediaan, jaringan, blok.
A36: Standar MI 5 Prosedur Penyimpanan dan pemeliharaan dokumen, spesimen, sampel, sediaan, jaringan, dan blok | B36: 3 | C36: 3) Rentang waktu penyimpanan untuk huruf a) sampai huruf g) pada angka 2) yang ditentukan sesuai dengan ketentuan peraturan perundang-undangan. | E36: [R] Regulasi tentang penetapan rentang waktu penyimpanan untuk huruf a) sampai huruf g) pada angka 2)
A37: Standar MI 5 Prosedur Penyimpanan dan pemeliharaan dokumen, spesimen, sampel, sediaan, jaringan, dan blok | B37: 4 | C37: 4) Laboratorium kesehatan mematuhi rentang waktu penyimpanan dokumen yang sudah ditetapkan untuk huruf g) pada angka 2). | E37: [D W O] Bukti penyimpanan dokumen huruf g) pada angka 2) sesuai rentang waktu penyimpanan yang sudah ditetapkan Penanggung jawab tiap unit Observasi dokumen sesuai huruf g) pada angka 2)
A38: Standar MI 5 Prosedur Penyimpanan dan pemeliharaan dokumen, spesimen, sampel, sediaan, jaringan, dan blok | B38: 5 | C38: 5) Terdapat bukti penilaian kepatuhan terhadap prosedur penyimpanan. | E38: [D] Bukti kepatuhan penyimpanan dokumen sesuai regulasi yang sudah ditetapkan
A39: Standar MI 5 Prosedur Penyimpanan dan pemeliharaan dokumen, spesimen, sampel, sediaan, jaringan, dan blok | B39: 6 | C39: 6) Ada tindakan perbaikan bila terdapat ketidaksesuaian dengan prosedur yang ditetapkan | E39: [D] Bukti tindakan perbaikan bila terdapat ketidaksesuaian dengan prosedur yang ditetapkan
A41: RINGKASAN CAPAIAN BAB III
A42: Standar | B42: Jumlah EP | C42: Total Skor | D42: Skor Maksimal | E42: Capaian (%)
...

Sheet Bab IV - KKS (Rinci)
A1: Bab IV. KUALIFIKASI DAN KOMPETENSI STAF (KKS) — KONTEN RESMI LENGKAP
A2: Sumber: Template Self Assessment Laboratorium Kesehatan resmi yang diberikan Bapak Hary Satrisno. Redaksi Elemen Penilaian dan Bukti/Telusur adalah teks ASLI.
A4: Standar | B4: No. EP | C4: Elemen Penilaian | D4: Skor Diri (0/5/10/TDD) | E4: Metode Telusur & Bukti | F4: Catatan / Rencana Tindak Lanjut
A5: Standar KKS 1 Kualifikasi dan kompetensi SDM — Pimpinan laboratorium kesehatan menetapkan persyaratan kualifikasi dan kompetensi bagi SDM laboratorium kesehatan
A6: Standar KKS 1 Kualifikasi dan kompetensi SDM | B6: 1 | C6: 1) Pimpinan laboratorium kesehatan menyusun perencanaan SDM laboratorium kesehatan sesuai kebutuhan, berdasarkan visi dan misi laboratorium kesehatan, analisis beban kerja, dan teknologi kesehatan yang digunakan di laboratorium kesehatan. | E6: [D] Bukti perhitungan kebutuhan SDM berdasarkan Analisis Beban Kerja (ABK)
A7: Standar KKS 1 Kualifikasi dan kompetensi SDM | B7: 2 | C7: 2) Pimpinan laboratorium kesehatan menetapkan persyaratan kualifikasi dan kompetensi bagi SDM laboratorium kesehatan sesuai dengan tugas pokok dan fungsi. | E7: [R] Regulasi Manajemen SDM meliputi perencanaan dan pengelolaan, pendidikan dan pelatihan, kesehatan dan keselamatan kerja.
A8: Standar KKS 1 Kualifikasi dan kompetensi SDM | B8: 3 | C8: 3) Tersedia SDM laboratorium kesehatan yang memiliki kualifikasi dan kompetensi sesuai dengan kebutuhan laboratorium kesehatan. | E8: [D] Data Kepegawaian sesuai kualifikasi dan kompetensi sesuai dengan kebutuhan laboratorium kesehatan.
A9: Standar KKS 1.1 Tanggung jawab dan uraian tugas SDM — SDM laboratorium kesehatan memiliki tanggung jawab sesuai dengan uraian tugas
A10: Standar KKS 1.1 Tanggung jawab dan uraian tugas SDM | B10: 1 | C10: 1) Setiap petugas memiliki uraian tugas | E10: [R] Regulasi Uraian Tugas: (SK petugas yang dilengkapi dengan uraian tugas)
A11: Standar KKS 1.1 Tanggung jawab dan uraian tugas SDM | B11: 2 | C11: 2) Uraian tugas mencakup huruf a) dan huruf b) sesuai dengan tugas dan tanggung jawabnya. | E11: [D] Bukti uraian tugas mencakup huruf (a) dan huruf (b) sesuai dengan tugas dan tanggung jawabnya.
A12: Standar KKS 1.1.1 Dokumen Kompetensi SDM
A13: Standar KKS 1.1.1 Dokumen Kompetensi SDM | B13: 1 | C13: 1) Terdapat Ijazah, STR dan surat izin untuk menjalankan praktek profesional untuk tenaga medis dan tenaga kesehatan serta terdapat ijazah untuk tenaga non kesehatan di laboratorium kesehatan. | E13: [D] Tenaga Medis dan tenaga kesehatan: jazah, STR dan SIP. Tenaga non kesehatan: ijazah
A14: Standar KKS 1.1.1 Dokumen Kompetensi SDM | B14: 2 | C14: 2) Terdapat bukti verifikasi ijazah, STR dan surat izin untuk menjalankan praktek profesional dari laboratorium kesehatan ke lembaga pendidikan/organisasi profesi yang mengeluarkan ijazah, STR dan surat izin untuk menjalankan praktek professional. | E14: [D W] Bukti verifikasi ijazah, STR dan SIP dari Laboratorium Kesehatan ke lembaga pendidikan / organisasi profesi yang mengeluarkan ijazah, STR dan SIP Kepala Tata Usaha Labkes/ Kepegawaian Labkes
A15: Standar KKS 1.2 Kualifikasi dan keahlian koordinator/penanggungjawab laboratorium kesehatan
A16: Standar KKS 1.2 Kualifikasi dan keahlian koordinator/penanggungjawab laboratorium kesehatan | B16: 1 | C16: 1) Koordinator/penanggung jawab laboratorium kesehatan memiliki kualifikasi, kompetensi dan pengalaman yang sesuai dengan tugas dan tanggungjawabnya. | E16: [D W] File kepegawaian koordinator/penanggung jawab laboratorium kesehatan sesuai kualifikasi, kompetensi dan pengalaman yang sesuai dengan tugas dan tanggung jawabnya. Kepala Tata Usaha Labkes/Kepegawaian Labkes dan Penanggung Jawab Labkes.
A17: Standar KKS 1.2 Kualifikasi dan keahlian koordinator/penanggungjawab laboratorium kesehatan | B17: 2 | C17: 2) Terdapat penetapan Koordinator/ penanggung jawab laboratorium kesehatan oleh pimpinan laboratorium kesehatan sesuai dengan peraturan perundang-undangan. | E17: [R] Regulasi: SK penetapan koordinator/penanggung jawab Laboratorium Kesehatan sesuai dengan peraturan perundang-undangan.
A18: Standar KKS 2 Program orientasi bagi SDM — SDM laboratorium kesehatan yang baru mengikuti program orientasi sebelum bertugas agar memahami tugas dan tanggung jawab di laboratorium kesehatan.
A19: Standar KKS 2 Program orientasi bagi SDM | B19: 1 | C19: 1) Semua SDM laboratorium kesehatan mengikuti program orientasi. | E19: [R D W] Program orientasi bagi SDM pemula, pegawai yang dirotasi di dalam lingkungan labkes, petugas dalam program pendidikan dan petugas magang sesuai maksud dan tujuan. Bukti pelaksanaan orientasi semua SDM Labkes Semua SDM Labkes
A20: Standar KKS 2 Program orientasi bagi SDM | B20: 2 | C20: 2) Pelaksanaan orientasi didokumentasikan. | E20: [D] Dokumentasi pelaksanaan orientasi
A21: Standar KKS 2.1 Program pelatihan dan pendidikan berkelanjutan bagi setiap SDM laboratorium kesehatan — Terdapat program pelatihan dan pendidikan berkelanjutan bagi setiap SDM laboratorium kesehatan untuk meningkatkan ketrampilan, pengetahuan dan kompete
A22: Standar KKS 2.1 Program pelatihan dan pendidikan berkelanjutan bagi setiap SDM laboratorium kesehatan | B22: 1 | C22: 1) Terdapat bukti identifikasi kebutuhan pelatihan dan/atau pendidikan berkelanjutan yang memuat paling sedikit salah satu dari huruf a) sampai huruf g). | E22: [D W] Bukti Identifikasi kebutuhan pelatihan dan/atau pendidikan berkelanjutan yang memuat paling sedikit salah satu huruf a) sampai huruf g). Kepala Tata Usaha/Kepegawain Labkes, Penanggung Jawab Tiap Unit.
A23: Standar KKS 2.1 Program pelatihan dan pendidikan berkelanjutan bagi setiap SDM laboratorium kesehatan | B23: 2 | C23: 2) Terdapat program pelatihan dan pendidikan berkelanjutan bagi SDM laboratorium kesehatan. | E23: [R] Program pelatihan dan Program pelatihan dan pendidikan berkelanjutan bagi SDM Labkes.
A24: Standar KKS 2.1 Program pelatihan dan pendidikan berkelanjutan bagi setiap SDM laboratorium kesehatan | B24: 3 | C24: 3) Terdapat bukti pelaksanaan kegiatan pelatihan dan pendidikan berkelanjutan. | E24: [D W] Bukti pelaksanaan kegiatan pelatihan dan pendidikan berkelanjutan. Kepala Tata Usaha/Kepegawaian Labkes, Penanggung Jawab Tiap Unit
A25: Standar KKS 3 Pemantauan, penilaian, evaluasi terhadap kinerja dan kompetensi SDM laboratorium kesehatan — Pemantauan, penilaian, evaluasi terhadap kinerja dan kompetensi SDM laboratorium kesehatan paling singkat 1 (satu) tahun sekali
A26: Standar KKS 3 Pemantauan, penilaian, evaluasi terhadap kinerja dan kompetensi SDM laboratorium kesehatan | B26: 1 | C26: 1) Terdapat kebijakan/prosedur evaluasi kinerja dan kompetensi SDM laboratorium kesehatan. | E26: [R] Regulasi: (Kebijakan/Prosedur) evaluasi kinerja dan kompetensi SDM Labkes
A27: Standar KKS 3 Pemantauan, penilaian, evaluasi terhadap kinerja dan kompetensi SDM laboratorium kesehatan | B27: 2 | C27: 2) Terdapat instrumen dan indikator penilaian kinerja dan kompetensi SDM laboratorium kesehatan. | E27: [D W] Bukti penilaian kinerja dan kompetensi SDM Labkes berupa instrumen (Checklist) yang berisi indikator penilaian kinerja dan kompetensi SDM Labkes. Kepala Labkes, Kepala Tata Usaha/Kepegawaian Labkes, Penanggung Jawab Tiap Unit dan SDM terkait.,
A28: Standar KKS 3.1 Dokumen data kepegawaian SDM — Dokumen data kepegawaian SDM Laboratorium kesehatan
A29: Standar KKS 3.1 Dokumen data kepegawaian SDM | B29: 1 | C29: 1) Laboratorium kesehatan menetapkan isi file data kepegawaian. | E29: [R] Regulasi: Kebijakan/Pedoman/Prosedur file kepegawaian yang meliputi angka1) sd 6) sesuai maksud dan tujuan.
A30: Standar KKS 3.1 Dokumen data kepegawaian SDM | B30: 2 | C30: 2) Terdapat bukti data kepegawaian yang mencakup angka 1) sampai angka 6). | E30: [D O W] Data Kepegawaian yang mencakup angka 1) sampai angka 6) File Kepegawaian Kepala Labkes, Kepala Tata Usaha/Kepegawaian Labkes, dan SDM Labkes
A31: Standar KKS 3.1 Dokumen data kepegawaian SDM | B31: 3 | C31: 3) Laboratorium kesehatan menetapkan penanggung jawab dokumen kepegawaian. | E31: [R] Regulasi: SK penetapan penanggung jawab dokumen kepegawaian
A32: Standar KKS 4 Program kesehatan dan keselamatan kerja SDM laboratorium kesehatan — Laboratorium kesehatan mempunyai program kesehatan dan keselamatan kerja SDM laboratorium
A33: Standar KKS 4 Program kesehatan dan keselamatan kerja SDM laboratorium kesehatan | B33: 1 | C33: 1) Terdapat program kesehatan dan keselamatan kerja serta program pemeriksaan kesehatan SDM di laboratorium kesehatan sesuai dengan ketentuan peraturan perundang-undangan. | E33: [R] Program kesehatan dan keselamatan kerja serta pemeriksaan kesehatan SDM di Laboratorium kesehatan.
A34: Standar KKS 4 Program kesehatan dan keselamatan kerja SDM laboratorium kesehatan | B34: 2 | C34: 2) Terdapat implementasi program kesehatan dan keselamatan kerja serta program pemeriksaan kesehatan SDM laboratorium kesehatan secara berkala. | E34: [D W] Bukti pelaksanaan program kesehatan dan keselamatan kerja serta program pemeriksaan kesehatan SDM Laboratorium Kesehatan secara berkala. Kepala Labkes, Kepala Tata Usaha/Kepegawaian Labkes, SDM Labkes
A35: Standar KKS 4 Program kesehatan dan keselamatan kerja SDM laboratorium kesehatan | B35: 3 | C35: 3) Dilakukan evaluasi dan tindak lanjut bagi SDM laboratorium kesehatan yang mengalami cedera akibat kecelakan kerja. | E35: [D] Bukti evaluasi dan tindak lanjut bagi SDM Laboratorium Kesehatan yang mengalami cedera akibat kecelakan kerja
A37: RINGKASAN CAPAIAN BAB IV
A38: Standar | B38: Jumlah EP | C38: Total Skor | D38: Skor Maksimal | E38: Capaian (%)
A39: Standar KKS 1 Kualifikasi dan kompetensi SDM | B39: 3 | C39: =SUMPRODUCT((D6:D8<>"TDD")*IFERROR(D6:D8,0)) -> 0 | D39: =COUNTIF(D6:D8,"<>TDD")*10 -> 30 | E39: =IFERROR(C39/D39,0) -> 0
A40: Standar KKS 1.1 Tanggung jawab dan uraian tugas SDM | B40: 2 | C40: =SUMPRODUCT((D10:D11<>"TDD")*IFERROR(D10:D11,0)) -> 0 | D40: =COUNTIF(D10:D11,"<>TDD")*10 -> 20 | E40: =IFERROR(C40/D40,0) -> 0
A41: Standar KKS 1.1.1 Dokumen Kompetensi SDM | B41: 2 | C41: =SUMPRODUCT((D13:D14<>"TDD")*IFERROR(D13:D14,0)) -> 0 | D41: =COUNTIF(D13:D14,"<>TDD")*10 -> 20 | E41: =IFERROR(C41/D41,0) -> 0
A42: Standar KKS 1.2 Kualifikasi dan keahlian koordinator/penanggungjawab laboratorium kesehatan | B42: 2 | C42: =SUMPRODUCT((D16:D17<>"TDD")*IFERROR(D16:D17,0)) -> 0 | D42: =COUNTIF(D16:D17,"<>TDD")*10 -> 20 | E42: =IFERROR(C42/D42,0) -> 0
...

Sheet Bab V - MFK (Rinci)
A1: Bab V. MANAJEMEN FASILITAS DAN KESELAMATAN (MFK) — KONTEN RESMI LENGKAP
A2: Sumber: Template Self Assessment Laboratorium Kesehatan resmi yang diberikan Bapak Hary Satrisno. Redaksi Elemen Penilaian dan Bukti/Telusur adalah teks ASLI.
A4: Standar | B4: No. EP | C4: Elemen Penilaian | D4: Skor Diri (0/5/10/TDD) | E4: Metode Telusur & Bukti | F4: Catatan / Rencana Tindak Lanjut
A5: Standar MFK 1 Standar Fasilitas — Pelayanan laboratorium kesehatan yang berkualitas perlu didukung dengan ketersediaan fasilitas sesuai standar dan klasifikasi laboratorium kesehatan,
A6: Standar MFK 1 Standar Fasilitas | B6: 1 | C6: 1) Terdapat kebijakan dan pedoman pengelolaan fasilitas sesuai dengan ketentuan peraturan perundang-undangan. | E6: [R] Regulasi : Kebijakan dan Pedoman pengelolaan fasilitas sesuai peraturan perundang-undangan
A7: Standar MFK 1 Standar Fasilitas | B7: 2 | C7: 2) Terdapat bukti implementasi pemenuhan standar fasilitas laboratorium kesehatan. | E7: [D W] Bukti implementasi pemenuhan standar fasilitas labkes (misalnya : inventarisasi fasilitas Laboratorium Kesehatan, analisis pemenuhan sesuai standar dan tindaklanjutnya) Pimpinan labkes
A8: Standar MFK 1 Standar Fasilitas | B8: 3 | C8: 3) Terdapat bukti evaluasi pemanfaatan fasilitas secara berkala dan ditindaklanjuti. | E8: [D] Bukti evaluasi dan tindak lanjut pemanfaatan fasilitas secara berkala
A9: Standar MFK 2 Standar ruang pelayanan — Ruangan untuk seluruh pelayanan sesuai standar
A10: Standar MFK 2 Standar ruang pelayanan | B10: 1 | C10: 1) Terdapat denah ruangan dan perlengkapan yang memadai untuk menjamin keamanan dan efektifitas pelayanan | E10: [D] Denah ruangan dan perlengkapan yang memadai untuk menjamin keamanan dan efektifitas pelayanan
A11: Standar MFK 2 Standar ruang pelayanan | B11: 2 | C11: 2) Terdapat ruang laboratorium yang aman dan nyaman untuk petugas, pasien dan pengunjung sesuai standar | E11: [O] Ruangan laboratorium yang aman dan nyaman untuk petugas, pasien dan pengunjung sesuai standar
A12: Standar MFK 2 Standar ruang pelayanan | B12: 3 | C12: 3) Terdapat ruang yang cukup untuk pelayanan mulai dari pengambilan, pengelolaan dan pemeriksaan sampel/spesimen | E12: [O] Ruangan yang cukup untuk pelayanan mulai dari pengambilan, pengelolaan dan pemeriksaan sampel/spesimen
A13: Standar MFK 2 Standar ruang pelayanan | B13: 4 | C13: 4) Terdapat ruang penempatan alat yang mudah diakses dan mempunyai ventilasi baik | E13: [O] Ruangan penyimpanan alat yang mudah diakses dan mempunyai ventilasi baik
A14: Standar MFK 2 Standar ruang pelayanan | B14: 5 | C14: 5) Terdapat ruang pengambilan sampel/spesimen yang memenuhi kriteria huruf a) sampai huruf e). | E14: [O] Ruang pengambilan sampel/spesimen yang memenuhi kriteria huruf a) sampai huruf e)
A15: Standar MFK 2 Standar ruang pelayanan | B15: 6 | C15: 6) Terdapat bukti bahwa sanitasi dan kebersihan seluruh area pelayanan terjamin sesuai standar | E15: [O] Sanitasi dan kebersihan seluruh area pelayanan terjamin sesuai standar
A16: Standar MFK 2.1 Standar ruang penyimpanan reagen, cairan, gas — Ruang penyimpanan reagen, cairan, gas yang mudah terbakar dan bahan-bahan lain yang dibutuhkan tersedia secara memadai dan terpelihara.
A17: Standar MFK 2.1 Standar ruang penyimpanan reagen, cairan, gas | B17: 1 | C17: 1) Terdapat pedoman/Standar Prosedur Operasional (SPO) tentang penyimpanan reagen, cairan, gas yang mudah terbakar dan bahan-bahan lainnya. | E17: [R] Regulasi : Pedoman/SPO tentang penyimpanan reagen, cairan, gas yang mudah terbakar dan bahan-bahan lainnya
A18: Standar MFK 2.1 Standar ruang penyimpanan reagen, cairan, gas | B18: 2 | C18: 2) Terdapat ruang penyimpanan reagen, cairan, gas yang mudah terbakar dan bahan-bahan lain yang dibutuhkan sesuai standar | E18: [O] Ruang penyimpanan reagen, cairan, gas yang mudah terbakar dan bahan-bahan lain yang dibutuhkan sesuai standar
A19: Standar MFK 2.1 Standar ruang penyimpanan reagen, cairan, gas | B19: 3 | C19: 3) Terdapat kontrol suhu dan kelembaban ruang penyimpanan. | E19: [D] Bukti monitoring kontrol suhu dan kelembaban ruang penyimpanan.
A20: Standar MFK 2.1 Standar ruang penyimpanan reagen, cairan, gas | B20: 4 | C20: 4) Terdapat bukti tertulis pemeliharaan ruang penyimpanan reagen, cairan, gas yang mudah terbakar dan bahan-bahan lainnya. | E20: [D] Bukti pemeliharaan ruang penyimpanan reagen, cairan, gas yang mudah terbakar dan bahan-bahan lainnya.
A21: Standar MFK 2.2 Keamanan dan kerahasiaan dokumen — Dokumen laboratorium kesehatan terjamin keamanan dan kerahasiaannya
A22: Standar MFK 2.2 Keamanan dan kerahasiaan dokumen | B22: 1 | C22: 1) Terdapat bukti kebijakan untuk menjaga kerahasiaan, keamanan, privasi, integritas data dan informasi. | E22: [R] Regulasi : kebijakan untuk menjaga kerahasiaan, keamanan, privasi, integritas data dan informasi
A23: Standar MFK 2.2 Keamanan dan kerahasiaan dokumen | B23: 2 | C23: 2) Terdapat bukti bahwa data dan informasi terjaga dari kerusakan. | E23: [D O] Daftar inventarisasi fasilitas labkes untuk menjaga keamanan data dan informasi terlindungi dari kerusakan Fasilitas labkes mendukung keamanan data dan informasi terlindungi dari kerusakan
A24: Standar MFK 2.2 Keamanan dan kerahasiaan dokumen | B24: 3 | C24: 3) Terdapat bukti bahwa hanya petugas yang berwenang yang dapat mengakses data dan informasi | E24: [D W] Daftar petugas yang berwenang yang dapat mengakses data dan informasi. Petugas labkes
A25: Standar MFK 2.2 Keamanan dan kerahasiaan dokumen | B25: 4 | C25: 4) Terdapat bukti penyimpanan data dan informasi yang terpelihara. | E25: [D] Bukti pemeliharaan penyimpanan data dan informasi secara berkala
A26: Standar MFK 3 Program pengelolaan prasarana — Program pengelolaan prasarana yang efektif dan efisien
A27: Standar MFK 3 Program pengelolaan prasarana | B27: 1 | C27: 1) Terdapat dokumen penetapan periode waktu pemeliharaan prasarana dengan mengacu pada tingkat risiko atau referensi lain. | E27: [R] Regulasi tentang penetapan periode waktu pemeliharaan prasarana dengan mengacu pada tingkat risiko atau referensi lain
A28: Standar MFK 3 Program pengelolaan prasarana | B28: 2 | C28: 2) Terdapat daftar prasarana yang sesuai pada maksud dan tujuan. | E28: [D] Daftar prasarana yang sesuai pada maksud dan tujuan
A29: Standar MFK 3 Program pengelolaan prasarana | B29: 3 | C29: 3) Terdapat pemantauan, pengujian dan pemeliharaan semua prasarana laboratorium kesehatan untuk memastikan bahwa semua prasarana terpelihara dan berfungsi dengan baik. | E29: [D] Bukti pemantauan, pengujian dan pemeliharaan semua prasarana laboratorium kesehatan untuk memastikan bahwa semua prasarana terpelihara dan berfungsi dengan baik.
A30: Standar MFK 3 Program pengelolaan prasarana | B30: 4 | C30: 4) Terdapat petunjuk untuk pemadaman darurat. | E30: [R] Regulasi tentang petunjuk pemadaman utilitas pada kondisi darurat
A31: Standar MFK 3.1 Pemantauan, pemeliharaan dan perbaikan prasarana — Dilakukan pemantauan, pemeliharaan dan perbaikan terhadap prasarana secara berkala sesuai peraturan perundang-undangan.
A32: Standar MFK 3.1 Pemantauan, pemeliharaan dan perbaikan prasarana | B32: 1 | C32: 1) Terdapat pengawasan terhadap prasarana yang dilakukan sesuai kriteria yang ditetapkan. | E32: [D O W] Bukti pengawasan terhadap prasarana yang dilakukan sesuai kriteria yang ditetapkan (contoh: check list pemantauan harian) Sistem utilitas Pimpinan labkes dan petugas terkait
A33: Standar MFK 3.1 Pemantauan, pemeliharaan dan perbaikan prasarana | B33: 2 | C33: 2) Terdapat pengujian prasarana sesuai kriteria yang ditetapkan | E33: [D] Bukti pengujian prasarana sesuai kriteria yang ditetapkan
A34: Standar MFK 3.1 Pemantauan, pemeliharaan dan perbaikan prasarana | B34: 3 | C34: 3) Terdapat pemeliharaan prasarana sesuai kriteria yang ditetapkan | E34: [D] Bukti pemeliharaan prasarana sesuai kriteria yang ditetapkan
A35: Standar MFK 3.2 Prasarana yang bersifat kritis dan ketersediaan sumber alternatif — Pemeliharaan prasarana yang bersifat kritis dan ketersediaan sumber alternatif secara berkala sesuai dengan ketentuan peraturan perundang-undangan.
A36: Standar MFK 3.2 Prasarana yang bersifat kritis dan ketersediaan sumber alternatif | B36: 1 | C36: 1) Terdapat prosedur untuk melakukan pengujian prasarana yang bersifat kritis. | E36: [R] Regulasi : Prosedur pengujian prasarana yang bersifat kritis.
A37: Standar MFK 3.2 Prasarana yang bersifat kritis dan ketersediaan sumber alternatif | B37: 2 | C37: 2) Terdapat dokumentasi inspeksi, hasil pengujian, dan pemantauan prasarana yang bersifat kritis. | E37: [D] Bukti hasil inspeksi, pengujian, dan pemantauan prasarana yang bersifat kritis
A38: Standar MFK 3.2 Prasarana yang bersifat kritis dan ketersediaan sumber alternatif | B38: 3 | C38: 3) Terdapat bukti tindakan perbaikan jika diperlukan. | E38: [D] Bukti tindakan perbaikan jika diperlukan
A39: Standar MFK 4.1 Uji fungsi, inspeksi, pemeliharaan, kalibrasi. — Laboratorium kesehatan menetapkan regulasi yang mengatur tentang uji fungsi, inspeksi, pemeliharaan, kalibrasi secara berkala terhadap semua peralatan
A40: Standar MFK 4.1 Uji fungsi, inspeksi, pemeliharaan, kalibrasi. | B40: 1 | C40: 1) Terdapat regulasi dan program pengelolaan peralatan. | E40: [R] Regulasi : program pengelolaan peralatan
A41: Standar MFK 4.1 Uji fungsi, inspeksi, pemeliharaan, kalibrasi. | B41: 2 | C41: 2) Terdapat daftar inventaris semua peralatan. | E41: [D] Daftar inventaris semua peralatan.
...

Sheet Bab VI - PM (Rinci)
A1: Bab VI. PENGENDALIAN MUTU (PM) — KONTEN RESMI LENGKAP
A2: Sumber: Template Self Assessment Laboratorium Kesehatan resmi yang diberikan Bapak Hary Satrisno. Redaksi Elemen Penilaian dan Bukti/Telusur adalah teks ASLI.
A4: Standar | B4: No. EP | C4: Elemen Penilaian | D4: Skor Diri (0/5/10/TDD) | E4: Metode Telusur & Bukti | F4: Catatan / Rencana Tindak Lanjut
A5: Standar PM 1 Pemantapan mutu internal dan eksternal. — Laboratorium kesehatan melakukan pemantapan mutu internal dan eksternal.
A6: Standar PM 1 Pemantapan mutu internal dan eksternal. | B6: 1 | C6: 1) Pimpinan laboratorium menetapkan prosedur pemantapan mutu untuk semua jenis pemeriksaan | E6: [R] Regulasi: Prosedur pemantapan mutu internal dan eksternal untuk semua jenis pemeriksaan
A7: Standar PM 1 Pemantapan mutu internal dan eksternal. | B7: 2 | C7: 2) Terdapat penerapan paling sedikit mencakup angka 6) huruf a) sampai huruf e). | E7: [D] Bukti penerapan/ implementasi paling sedikit mencakup angka 6) huruf a) sampai dengan huruf e)
A8: Standar PM 1 Pemantapan mutu internal dan eksternal. | B8: 3 | C8: 3) Terdapat evaluasi dan tindak lanjut dari hasil pemantapan mutu internal dan eksternal. | E8: [D] Bukti evaluasi dan tindak lanjut berdasarkan hasil pemantapan mutu internal dan eksternal
A9: Standar PM 1.1 Uji profisiensi — Laboratorium kesehatan mengikuti uji profisiensi
A10: Standar PM 1.1 Uji profisiensi | B10: 1 | C10: 1) Terdapat bukti hasil uji profisiensi dari laboratorium kesehatan untuk setiap pemeriksaan | E10: [D W] Bukti hasil uji profisiensi dari laboratorium kesehatan untuk setiap pemeriksaan. Petugas Labkes yang melakukan uji profisiensi
A11: Standar PM 1.1 Uji profisiensi | B11: 2 | C11: 2) Terdapat laporan hasil pemeriksaan uji profisiensi dari laboratorium kesehatan ke penyelenggara dalam kurun waktu yang telah ditentukan | E11: [D W] Bukti laporan hasil pemeriksaan uji profisiensi dari laboratorium kesehatan ke penyelenggara dalam kurun waktu yang telah ditentukan. Pimpinan Labkes, Tim Mutu.
A12: Standar PM 1.1 Uji profisiensi | B12: 3 | C12: 3) Terdapat bukti bahwa laboratorium kesehatan telah mengikuti ketentuan penyelenggara uji profisiensi | E12: [D W] Bukti Laboratorium Kesehatan mengikuti ketentuan penyelenggara uji profisiensi. Petugas Labkes yang melakukan uji Profisiensi.
A13: Standar PM 1.1 Uji profisiensi | B13: 4 | C13: 4) Terdapat bukti bahwa laboratorium kesehatan telah melakukan evaluasi dan tindak lanjuti terhadap nilai yang diperoleh dari penyelenggara meliputi angka 4 huruf d) dan angka 5) | E13: [D] Bukti evaluasi dan tindak lanjut yang diperoleh dari penyelenggara yang meliputi angka 4 huruf d) dan angka 5).
A14: Standar PM 1.1.1 Pengelolaan sampel uji profisiensi. — Sampel atau spesimen pada uji profisiensi diperiksa seperti pemeriksaan sampel atau spesimen rutin dengan reagen/ peralatan/ metode yang biasa digunak
A15: Standar PM 1.1.1 Pengelolaan sampel uji profisiensi. | B15: 1 | C15: 1). Terdapat bukti bahwa uji profisiensi telah dilaksanakan oleh petugas yang biasa melakukan pemeriksaan dengan reagen/ peralatan/ metode yang biasa digunakan | E15: [D] Bukti uji profisiensi dilakukan oleh petugas yang biasa melakukan pemeriksaan dengan reagen/ peralatan/ metode yang biasa digunakan
A16: Standar PM 1.1.1 Pengelolaan sampel uji profisiensi. | B16: 2 | C16: 2). Terdapat bukti bahwa uji profisiensi telah dikerjakan seperti prosedur pemeriksaan rutin. | E16: [D W] Bukti laporan pelaksanaan uji profisiensi yang dikerjakan seperti prosedur pemeriksaan rutin. Petugas yang melaksanakan uji profisiensi, Penanggung Jawab Mutu
A17: Standar PM 1.1.2 Alternatif uji profisiensi. — Laboratorium yang tidak dapat mengikuti uji profisiensi karena penyelenggara uji profisiensi tidak ada, maka harus melakukan upaya lain untuk menjami
A18: Standar PM 1.1.2 Alternatif uji profisiensi. | B18: 1 | C18: 1) Terdapat bukti upaya dari laboratorium kesehatan untuk melakukan kegiatan untuk menjamin mutu hasil pemeriksaan laboratorium kesehatan meliputi angka 1) mencakup huruf a) sampai dengan huruf d) (berjenjang sesuai urutan prioritas) | E18: [D W] Bila tidak terdapat lembaga penyelenggara uji profisiensi maka laboratorium Kesehatan memiliki bukti melakukan penjaminan mutu hasil pemeriksaan meliputi angka 1) mencakup huruf a) sampai dengan huruf d) (berjenjang sesuai urutan prioritas). Pimpinan Labkes, Petugas yang melakukan uji profisiensi
A19: Standar PM 1.1.2 Alternatif uji profisiensi. | B19: 2 | C19: 2) Terdapat bukti bahwa laboratorium kesehatan melakukan evaluasi dan tindak lanjut terhadap hasil uji serta didokumentasikan paling singkat 3 (tiga) tahun. | E19: [D] Bukti evaluasi dan tindak lanjut terhadap hasil uji profisiensi serta didokumentasikan paling singkat 3 (tiga) tahun.
A20: Standar PM 1.2 Pengelolaan hasil pemeriksaan dengan lebih dari 1 (satu) alat — Laboratorium kesehatan menetapkan prosedur untuk evaluasi dan penetapan korelasi antara dua hasil pemeriksaan dengan sampel/spesimen yang sama tetapi
A21: Standar PM 1.2 Pengelolaan hasil pemeriksaan dengan lebih dari 1 (satu) alat | B21: 1 | C21: 1) Terdapat prosedur untuk menetapkan kesesuaian antara dua hasil pemeriksaan dengan sampel yang sama tetapi diperiksa dengan menggunakan metode atau alat yang berbeda mengacu pada batas keberterimaan sesuai peraturan perundang-undangan yang berlaku. | E21: [R] Regulasi: prosedur penetapan korelasi antara dua hasil pemeriksaan dengan sampel/spesimen yang sama, penetapan jumlah spesimen yang akan diperiksa/ dibandingkan dan menentukan rentang hasil yang dapat diterima, tetapi diperiksa dengan menggunakan metode atau alat yang berbeda, dan penetapan metode jika ditemukan perbedaan hasil yang sangat bermakna.
A22: Standar PM 1.2 Pengelolaan hasil pemeriksaan dengan lebih dari 1 (satu) alat | B22: 2 | C22: 2) Terdapat uji kesesuaian dilakukan paling sedikit 2 (dua) kali dalam 1 (satu) tahun. | E22: [D] Bukti uji kesesuaian yang dilakukan paling sedikit 2 (dua) kali dalam 1 (satu) tahun.
A23: Standar PM 1.2 Pengelolaan hasil pemeriksaan dengan lebih dari 1 (satu) alat | B23: 3 | C23: 3) Terdapat penetapan jumlah spesimen yang akan diperiksa/ dibandingkan dan menentukan rentang hasil yang dapat diterima. | E23: [D] Bukti implementasi penetapan jumlah spesimen yang akan diperiksa/ dibandingkan dan menentukan rentang hasil yang dapat diterima.
A24: Standar PM 1.2 Pengelolaan hasil pemeriksaan dengan lebih dari 1 (satu) alat | B24: 4 | C24: 4) Jika ditemukan perbedaan hasil yang sangat bermakna, pimpinan laboratorium kesehatan harus menetapkan metode mana yang akan digunakan. | E24: [D W] Bukti implementasi metode yang akan digunakan jika ditemukan perbedaan hasil yang sangat bermakna. Pimpinan Labkes
A25: Standar PM 1.3 Validasi dan verifikasi alat, metode dan perangkat lunak — Laboratorium kesehatan melakukan validasi awal/ verifikasi terhadap alat baru, metode baru dan sistem analisa perangkat lunak/software) sebelum diguna
A26: Standar PM 1.3 Validasi dan verifikasi alat, metode dan perangkat lunak | B26: 1 | C26: 1) Terdapat bukti laboratorium kesehatan menetapkan jumlah dan jenis bahan kontrol serta frekuensi quality control pada saat melakukan validasi. | E26: [R D] Regulasi : penetapan jumlah dan jenis bahan kontrol serta frekuensi quality control pada saat melakukan validasi. Bukti implementasi penetapan jumlah dan jenis bahan kontrol serta frekuensi quality control pada saat melakukan validasi.
A27: Standar PM 1.3 Validasi dan verifikasi alat, metode dan perangkat lunak | B27: 2 | C27: 2) Terdapat bukti laboratorium kesehatan melakukan validasi terhadap semua metode baru yang digunakan dan terdokumentasi. | E27: [D] Bukti dilakukan validasi terhadap semua metode baru yang digunakan dan terdokumentasi.
A28: Standar PM 1.3 Validasi dan verifikasi alat, metode dan perangkat lunak | B28: 3 | C28: 3) Terdapat bukti untuk setiap metode analitik, dilakukan paling sedikit uji akurasi, uji presisi dan penetapan rentang nilai hasil pemeriksaan. | E28: [D] Bukti dilakukan uji akurasi, uji presisi dan penetapan rentang nilai hasil pemeriksaan.
A29: Standar PM 1.4 Validasi sistem pemantauan internal atau elektronik — Laboratorium kesehatan melakukan validasi terhadap sistem pemantauan internal atau elektronik dalam pelaksanaan pemantapan mutu.
A30: Standar PM 1.4 Validasi sistem pemantauan internal atau elektronik | B30: 1 | C30: 1) Terdapat bukti Laboratorium melakukan validasi terhadap sistem pemantauan mutu internal atau elektronik yang digunakan dalam pelaksanaan pemantapan mutu. | E30: [D] Bukti validasi terhadap sistem pemantauan mutu internal atau elektronik yang digunakan.
A31: Standar PM 1.4 Validasi sistem pemantauan internal atau elektronik | B31: 2 | C31: 2) Terdapat Bukti adanya Sistem pemantauan mutu yang digunakan untuk memenuhi angka 1) dan angka 2) | E31: [D] Bukti pelaksanaan sistem pemantauan mutu yang digunakan untuk memenuhi angka 1) dan angka 2) pada maksud dan tujuan.
A32: Standar PM 1.4 Validasi sistem pemantauan internal atau elektronik | B32: 3 | C32: 3) Terdapat Bukti Proses validasi mencakup angka 3) sampai dengan angka 5) | E32: [D] Bukti proses validasi yang mencakup angka 3) sampai dengan angka 5) pada maksud dan tujuan.
A33: Standar PM 1.4 Validasi sistem pemantauan internal atau elektronik | B33: 4 | C33: 4) Terdapat Bukti bahwa frekuensi pelaksanaan pemantapan mutu internal dan eksternal memperhatikan angka 6) sampai dengan angka 8). | E33: [D] Bukti frekuensi pelaksanaan pemantapan mutu internal dan eksternal memperhatikan angka 6) sampai dengan angka 8) pada maksud dan tujuan.
A34: Standar PM 1.4 Validasi sistem pemantauan internal atau elektronik | B34: 5 | C34: 5) Terdapat Bukti Jika nilai kontrol tidak dapat diterima laboratorium kesehatan mengidentifikasi penyebabnya dan mengulang kembali proses validasi | E34: [D] Bukti dilakukan identifikasi penyebab dan pengulangan proses validasi Jika nilai kontrol tidak dapat diterima.
A35: Standar PM 1.5 Kalibrasi alat dan uji fungsi alat — Laboratorium kesehatan melakukan kalibrasi alat dan uji fungsi alat.
A36: Standar PM 1.5 Kalibrasi alat dan uji fungsi alat | B36: 1 | C36: 1) Terdapat Bukti bahwa laboratorium kesehatan melakukan kalibrasi alat dan uji fungsi alat sesuai prosedur yang telah ditetapkan. | E36: [D] Bukti kalibrasi alat dan uji fungsi alat sesuai prosedur yang telah ditetapkan
A37: Standar PM 1.5 Kalibrasi alat dan uji fungsi alat | B37: 2 | C37: 2) Terdapat Bukti prosedur kalibrasi harus mengikuti kriteria dari pabrik alat | E37: [R D] Regulasi : prosedur kalibrasi alat Bukti implementasi prosedur kalibrasi
A38: Standar PM 1.5 Kalibrasi alat dan uji fungsi alat | B38: 3 | C38: 3) Terdapat Bukti laboratorium mendokumentasikan pelaksanaan kalibrasi. | E38: [D] Bukti pelaksanaan kalibrasi
A39: Standar PM 1.6 Pemantapan Mutu Internal (PMI) — Proses kendali mutu meliputi evaluasi hasil pemeriksaan laboratorium kesehatan, hasil pemantapan mutu internal dan hasil uji kinerja harian alat.
A40: Standar PM 1.6 Pemantapan Mutu Internal (PMI) | B40: 1 | C40: 1) Terdapat bukti bahwa hasil pemeriksaan dievaluasi setiap hari. | E40: [D] Bukti evaluasi hasil pemeriksaan yang dilakukan setiap hari.
A41: Standar PM 1.6 Pemantapan Mutu Internal (PMI) | B41: 2 | C41: 2) Terdapat bukti laporan hasil pemeriksaan secara manual maupun elektronik, dievaluasi untuk mengurangi terjadinya kesalahan. | E41: [D] Bukti laporan hasil pemeriksaan secara manual maupun elektronik, dan hasil evaluasi untuk mengurangi terjadinya kesalahan.
...

Sheet Bab VII - PPN (Rinci)
A1: Bab VII. PROGRAM PRIORITAS NASIONAL (PPN) — KONTEN RESMI LENGKAP
A2: Sumber: Template Self Assessment Laboratorium Kesehatan resmi yang diberikan Bapak Hary Satrisno. Redaksi Elemen Penilaian dan Bukti/Telusur adalah teks ASLI.
A4: Standar | B4: No. EP | C4: Elemen Penilaian | D4: Skor Diri (0/5/10/TDD) | E4: Metode Telusur & Bukti | F4: Catatan / Rencana Tindak Lanjut
A5: Standar PPN 1 Kewajiban laboratorium kesehatan mendukung program pengendalian HIV — Laboratorium wajib mendukung pemerintah dalam pengendalian HIV
A6: Standar PPN 1 Kewajiban laboratorium kesehatan mendukung program pengendalian HIV | B6: 1 | C6: 1) Terdapat bukti bahwa laboratorium melakukan komunikasi dan koordinasi dengan lintas terkait untuk menjamin terlaksananya penanggulangan HIV. | E6: [D W] Bukti komunikasi dan koordinasi dengan lintas terkait untuk menjamin terlaksananya penanggulangan HIV. Kepala Labkes, Penanggung Jawab Tiap Unit, Penanggung Jawab Mutu.
A7: Standar PPN 1 Kewajiban laboratorium kesehatan mendukung program pengendalian HIV | B7: 2 | C7: 2) Terdapat bukti bahwa laboratorium kesehatan menerapkan upaya penanggulangan HIV sesuai dengan hasil komunikasi dan koordinasi dengan lintas terkait. | E7: [D] Bukti penerapan upaya penanggulangan HIV sesuai dengan hasil komunikasi dan koordinasi dengan lintas terkait
A8: Standar PPN 2. Kewajiban laboratorium kesehatan mendukung program pengendalian TB — Laboratorium wajib mendukung pemerintah dalam pengendalian TB
A9: Standar PPN 2. Kewajiban laboratorium kesehatan mendukung program pengendalian TB | B9: 1 | C9: 1) Terdapat bukti bahwa laboratorium melakukan komunikasi dan koordinasi dengan lintas terkait untuk menjamin terlaksananya penanggulangan TB. | E9: [D W] Bukti komunikasi dan koordinasi dengan lintas terkait untuk menjamin terlaksananya penanggulangan TB. Kepala Labkes, Penanggung Jawab Tiap Unit, Penanggung Jawab Mutu
A10: Standar PPN 2. Kewajiban laboratorium kesehatan mendukung program pengendalian TB | B10: 2 | C10: 2) Terdapat bukti bahwa laboratorium kesehatan menerapkan upaya penanggulangan TB sesuai dengan hasil komunikasi dan koordinasi dengan lintas terkait | E10: [D] Bukti penerapan upaya penanggulangan TB sesuai dengan hasil komunikasi dan koordinasi dengan lintas terkait.
A11: Standar PPN. 3. Kewajiban laboratorium kesehatan mendukung program penurunan AKI/AKB — Laboratorium wajib mendukung pemerintah dalam menurunkan AKI/AKB
A12: Standar PPN. 3. Kewajiban laboratorium kesehatan mendukung program penurunan AKI/AKB | B12: 1 | C12: 1) Terdapat bukti bahwa laboratorium melakukan komunikasi dan koordinasi dengan lintas terkait dalam menurunkan AKI/AKB. | E12: [D W] Bukti komunikasi dan koordinasi dengan lintas terkait dalam menurunkan AKI/AKB Kepala Labkes, Penanggung Jawab Tiap Unit, Penanggung Jawab Mutu
A13: Standar PPN. 3. Kewajiban laboratorium kesehatan mendukung program penurunan AKI/AKB | B13: 2 | C13: 2) Terdapat bukti bahwa laboratorium kesehatan menerapkan upaya dalam menurunkan AKI/AKB sesuai dengan hasil komunikasi dan koordinasi dengan lintas terkait. | E13: [D] Bukti penerapan upaya penanggulangan AKI/AKB sesuai dengan hasil komunikasi dan koordinasi dengan lintas terkait.
A15: RINGKASAN CAPAIAN BAB VII
A16: Standar | B16: Jumlah EP | C16: Total Skor | D16: Skor Maksimal | E16: Capaian (%)
A17: Standar PPN 1 Kewajiban laboratorium kesehatan mendukung program pengendalian HIV | B17: 2 | C17: =SUMPRODUCT((D6:D7<>"TDD")*IFERROR(D6:D7,0)) -> 0 | D17: =COUNTIF(D6:D7,"<>TDD")*10 -> 20 | E17: =IFERROR(C17/D17,0) -> 0
A18: Standar PPN 2. Kewajiban laboratorium kesehatan mendukung program pengendalian TB | B18: 2 | C18: =SUMPRODUCT((D9:D10<>"TDD")*IFERROR(D9:D10,0)) -> 0 | D18: =COUNTIF(D9:D10,"<>TDD")*10 -> 20 | E18: =IFERROR(C18/D18,0) -> 0
A19: Standar PPN. 3. Kewajiban laboratorium kesehatan mendukung program penurunan AKI/AKB | B19: 2 | C19: =SUMPRODUCT((D12:D13<>"TDD")*IFERROR(D12:D13,0)) -> 0 | D19: =COUNTIF(D12:D13,"<>TDD")*10 -> 20 | E19: =IFERROR(C19/D19,0) -> 0
A20: TOTAL BAB VII | B20: =SUM(B17:B19) -> 6 | C20: =SUM(C17:C19) -> 0 | D20: =SUM(D17:D19) -> 60 | E20: =IFERROR(C20/D20,0) -> 0

Sheet Rekap Capaian
A1: REKAPITULASI CAPAIAN SELURUH BAB
A3: No | B3: Bab | C3: Jumlah EP | D3: Total Skor | E3: Skor Maksimal | F3: Capaian (%)
A4: 1 | B4: Bab I. SASARAN KESELAMATAN PASIEN (SKP) | C4: 6 | D4: ='Bab I - SKP (Rinci)'!C20 -> 0 | E4: ='Bab I - SKP (Rinci)'!D20 -> 60 | F4: =IFERROR(D4/E4,0) -> 0
A5: 2 | B5: Bab II. TATA KELOLA KEPEMIMPINAN (TKK) | C5: 55 | D5: ='Bab II - TKK (Rinci)'!C101 -> 0 | E5: ='Bab II - TKK (Rinci)'!D101 -> 550 | F5: =IFERROR(D5/E5,0) -> 0
A6: 3 | B6: Bab III. MANAJEMEN INFORMASI (MI) | C6: 27 | D6: ='Bab III - MI (Rinci)'!C51 -> 0 | E6: ='Bab III - MI (Rinci)'!D51 -> 270 | F6: =IFERROR(D6/E6,0) -> 0
A7: 4 | B7: Bab IV. KUALIFIKASI DAN KOMPETENSI STAF (KKS) | C7: 22 | D7: ='Bab IV - KKS (Rinci)'!C48 -> 0 | E7: ='Bab IV - KKS (Rinci)'!D48 -> 220 | F7: =IFERROR(D7/E7,0) -> 0
